<mujoco model="bolt">
    <include file="simulation_scene.xml"/>

    <asset>
        <mesh name="bolt_body" file="bolt_body.stl" />
        <mesh name="bolt_hip_fe_left_side" file="bolt_hip_fe_left_side.stl" />
        <mesh name="upper_leg_200mm_left_side" file="upper_leg_200mm_left_side.stl" />
        <mesh name="lower_leg_200mm_left_side" file="lower_leg_200mm_left_side.stl" />
        <mesh name="bolt_hip_fe_right_side" file="bolt_hip_fe_right_side.stl" />
        <mesh name="upper_leg_200mm_right_side" file="upper_leg_200mm_right_side.stl" />
        <mesh name="lower_leg_200mm_right_side" file="lower_leg_200mm_right_side.stl" />

        <texture type="skybox" builtin="gradient" width="128" height="128" rgb1="0.4 0.6 0.8" rgb2="0 0 0"/>
        <texture name="texgeom" type="cube" builtin="flat" mark="cross" width="128" height="128" rgb1="0.6 0.6 0.6" rgb2="0.6 0.6 0.6" markrgb="1 1 1"/>
        <texture name="texplane" type="2d" builtin="checker" rgb1=".4 .4 .4" rgb2=".6 .6 .6" width="512" height="512"/>
        <material name="geom" texture="texgeom" texuniform="true"/>
        <material name="MatPlane" reflectance="0.3" texture="texplane" texrepeat="1 1" texuniform="true"/>
        <material name="MatPlane2" reflectance="0.3"/>
    </asset>

    <worldbody>
        <geom name="ground" type="plane" pos="0 0 0" size="10 10 .05" rgba="0.7 0.6 0.5 1" material="MatPlane" group="3"/>
        <light directional="true" diffuse=".8 .8 .8" pos="0 0 10" dir="0 0 -10"/>
        <light directional="true" diffuse=".5 .5 .5" pos="10 0 0" dir="-10 0 0"/>

        <body name="base_link" pos="0 0 0">
            <inertial pos="0 0 0" quat="0 0.707107 0 0.707107" mass="0.614369" diaginertia="0.0247612 0.0193811 0.00578574" />
            <joint name="virtual" type="free" />
            <geom type="mesh" rgba="0.0 0.0 0.0 1" mesh="bolt_body" />
            <site name="Pelvis_IMU" type="cylinder" size="0.005 0.005" group="4" rgba=".1 .1 .9 1"/>
            <body name="FL_SHOULDER" pos="0 0.0636 0">
                <inertial pos="0.0170826 -0.00446892 -0.0109583" quat="0.380445 0.573263 0.68117 0.250275" mass="0.140043" diaginertia="0.000140999 0.000103321 5.85997e-05" />
                <joint name="FL_HAA" pos="0 0 0" axis="1 0 0" limited="true" range="-10 10" />
                <geom type="mesh" rgba="0.0 0.0 0.0 1" mesh="bolt_hip_fe_left_side" />
                <body name="FL_UPPER_LEG" pos="0 0.0145 -0.0386">
                    <inertial pos="1.377e-05 0.0193585 -0.118707" quat="0.705243 -0.0424536 0.0423607 0.706424" mass="0.148538" diaginertia="0.000417563 0.00041107 2.46069e-05" />
                    <joint name="FL_HFE" pos="0 0 0" axis="0 1 0" limited="true" range="-10 10" />
                    <geom type="mesh" rgba="0.0 0.0 0.0 1" mesh="upper_leg_200mm_left_side" />
                    <body name="FL_LOWER_LEG" pos="0 0.0374 -0.2">
                        <inertial pos="0 0.00836718 -0.115919" quat="0.707082 -0.00592354 0.00592354 0.707082" mass="0.0311724" diaginertia="0.000115592 0.00011487 2.16816e-06" />
                        <joint name="FL_KFE" pos="0 0 0" axis="0 1 0" limited="true" range="-10 10" />
                        <geom type="mesh" rgba="0.0 0.0 0.0 1" mesh="lower_leg_200mm_left_side" />
                        <body name="FL_FOOT" pos="0 0.008 -0.2">
                            <inertial pos="0 0 0.00035767" quat="0.707107 0 0 0.707107" mass="0.012" diaginertia="1.5e-07 1.0e-05 0.98e-05" />
                            <joint name="FL_ANKLE" pos="0 0 0" axis="0 1 0" limited="false" range="-3.14 3.14" />
                            <geom size="0.008 0.05" pos="0 0 -0.01" quat="0.707107 0 0.707107 0" type="cylinder" rgba="0.0 0.0 0.0 1" />
                        </body>
                    </body>
                </body>
            </body>
            <body name="FR_SHOULDER" pos="0 -0.0636 0">
                <inertial pos="0.0170823 0.00447099 -0.0109585" quat="0.250376 0.681095 0.573344 0.380393" mass="0.140044" diaginertia="0.000141003 0.000103316 5.8591e-05" />
                <joint name="FR_HAA" pos="0 0 0" axis="1 0 0" limited="true" range="-10 10" />
                <geom type="mesh" rgba="0.0 0.0 0.0 1" mesh="bolt_hip_fe_right_side" />
                <body name="FR_UPPER_LEG" pos="0 -0.0145 -0.0386">
                    <inertial pos="-1.377e-05 -0.0193585 -0.118707" quat="0.705243 0.0424536 -0.0423607 0.706424" mass="0.148538" diaginertia="0.000417563 0.00041107 2.46069e-05" />
                    <joint name="FR_HFE" pos="0 0 0" axis="0 1 0" limited="true" range="-10 10" />
                    <geom type="mesh" rgba="0.0 0.0 0.0 1" mesh="upper_leg_200mm_right_side" />
                    <body name="FR_LOWER_LEG" pos="0 -0.0374 -0.2">
                        <inertial pos="0 -0.00836718 -0.115919" quat="0.707082 0.00592354 -0.00592354 0.707082" mass="0.0311724" diaginertia="0.000115592 0.00011487 2.16816e-06" />
                        <joint name="FR_KFE" pos="0 0 0" axis="0 1 0" limited="true" range="-10 10" />
                        <geom type="mesh" rgba="0.0 0.0 0.0 1" mesh="lower_leg_200mm_right_side" />
                        <body name="FR_FOOT" pos="0 -0.008 -0.2">
                            <inertial pos="0 0 0.00035767" quat="0.707107 0 0 0.707107" mass="0.012" diaginertia="1.5e-07 1.0e-05 0.98e-05" />
                            <joint name="FR_ANKLE" pos="0 0 0" axis="0 1 0" limited="false" range="-3.14 3.14" />
                            <geom size="0.008 0.05" pos="0 0 -0.01" quat="0.707107 0 0.707107 0" type="cylinder" rgba="0.0 0.0 0.0 1" />
                        </body>
                    </body>
                </body>
            </body>
        </body>
    </worldbody>

    <actuator>
		<position class="position" ctrllimited="true" ctrlrange="-3 3" name="FL_HAA" joint="FL_HAA" kp = "30"/> 
		<position class="position" ctrllimited="true" ctrlrange="-3 3" name="FL_HFE" joint="FL_HFE" kp = "30"/> 
		<position class="position" ctrllimited="true" ctrlrange="-3 3" name="FL_KFE" joint="FL_KFE" kp = "30"/> 
		<position class="position" ctrllimited="true" ctrlrange="-3 3" name="FL_ANKLE" joint="FL_ANKLE" kp = "15"/> 
		<!-- <motor name="FL_ANKLE" joint="FL_ANKLE" />  -->
		<position class="position" ctrllimited="true" ctrlrange="-3 3" name="FR_HAA" joint="FR_HAA" kp = "30"/> 
		<position class="position" ctrllimited="true" ctrlrange="-3 3" name="FR_HFE" joint="FR_HFE" kp = "30"/> 
		<position class="position" ctrllimited="true" ctrlrange="-3 3" name="FR_KFE" joint="FR_KFE" kp = "30"/> 
		<position class="position" ctrllimited="true" ctrlrange="-3 3" name="FR_ANKLE" joint="FR_ANKLE" kp = "15"/> 
		<!-- <motor name="FR_ANKLE" joint="FR_ANKLE" />  -->
    </actuator>  

    <sensor>
        <accelerometer name="Acc_Pelvis_IMU" site="Pelvis_IMU"/>
        <gyro name="Gyro_Pelvis_IMU" site="Pelvis_IMU"/>
        <magnetometer name="Magnet_Pelvis_IMU" site="Pelvis_IMU"/>

        <framequat name="Pelvis_quat" objtype="site" objname="Pelvis_IMU"/>
        <framelinvel name="Pelvis_linear_vel" objtype="site" objname="Pelvis_IMU"/>
		<frameangvel name="Pelvis_angular_vel" objtype="site" objname="Pelvis_IMU"/>  
    </sensor>

    <keyframe>
        <key name="front" time="0" qpos="0 0 0.43 1 0 0 0
                                        
                                        0 0.436332313 -0.872664626 0.436332313
                                        0 0.436332313 -0.872664626 0.436332313"/>
    </keyframe>
</mujoco>
<!-- 0 0 0 -0.785398163 0 0 0 -0.785398163"/> -->
                                         <!-- 0 0 0 0 0 0 0 0"/> -->
